Workbook

Sheet Dark
A1: Date | B1: Time | C1: MOD_ID | D1: CMD_CNT | E1: ERROR | F1: MTR_ABS_STEPS | G1: THRM_STATUS | H1: SWIR_OFFSET | I1: MWIR_OFFSET | J1: SCI_ADC_SAMPLES | K1: SCI_ADC_SKIP | L1: SWIR_HIGH | M1: SWIR_MED | N1: SWIR_LOW | O1: MWIR_HIGH | P1: MWIR_MED | Q1: MWIR_LOW | R1: HT_SINK_TEMP | S1: SWIR_TEMP | T1: CRC
A2: 45888 | B2: 0.80381722 | C2: 79 | D2: 238 | E2: 0 | F2: 8 | G2: 0 | H2: 2368 | I2: 1784 | J2: 0 | K2: 100 | L2: 174 | M2: 6 | N2: 2 | O2: 3947 | P2: 155 | Q2: 6 | R2: 404 | S2: 398 | T2: 207
A3: 45888 | B3: 0.8038298 | C3: 79 | D3: 242 | E3: 0 | F3: 8 | G3: 0 | H3: 2368 | I3: 1784 | J3: 0 | K3: 100 | L3: 166 | M3: 6 | N3: 0 | O3: 3950 | P3: 158 | Q3: 6 | R3: 404 | S3: 397 | T3: 157
A4: 45888 | B4: 0.80384552 | C4: 79 | D4: 247 | E4: 0 | F4: 8 | G4: 0 | H4: 2368 | I4: 1784 | J4: 0 | K4: 100 | L4: 170 | M4: 6 | N4: 1 | O4: 3954 | P4: 161 | Q4: 6 | R4: 404 | S4: 398 | T4: 8
A5: 45888 | B5: 0.8038615 | C5: 79 | D5: 252 | E5: 0 | F5: 8 | G5: 0 | H5: 2368 | I5: 1784 | J5: 0 | K5: 100 | L5: 165 | M5: 6 | N5: 1 | O5: 3958 | P5: 166 | Q5: 6 | R5: 404 | S5: 398 | T5: 252
A6: 45888 | B6: 0.80387749 | C6: 79 | D6: 1 | E6: 0 | F6: 8 | G6: 0 | H6: 2368 | I6: 1784 | J6: 0 | K6: 100 | L6: 170 | M6: 6 | N6: 0 | O6: 3961 | P6: 168 | Q6: 6 | R6: 404 | S6: 398 | T6: 32
A7: 45888 | B7: 0.80389346 | C7: 79 | D7: 6 | E7: 0 | F7: 8 | G7: 0 | H7: 2368 | I7: 1784 | J7: 0 | K7: 100 | L7: 171 | M7: 6 | N7: 0 | O7: 3964 | P7: 172 | Q7: 7 | R7: 404 | S7: 398 | T7: 162
A8: 45888 | B8: 0.80390938 | C8: 79 | D8: 11 | E8: 0 | F8: 0 | G8: 0 | H8: 2368 | I8: 1784 | J8: 0 | K8: 100 | L8: 180 | M8: 6 | N8: 1 | O8: 3969 | P8: 178 | Q8: 6 | R8: 404 | S8: 398 | T8: 1
A9: 45888 | B9: 0.80392534 | C9: 79 | D9: 16 | E9: 0 | F9: 0 | G9: 0 | H9: 2368 | I9: 1784 | J9: 0 | K9: 100 | L9: 178 | M9: 6 | N9: 2 | O9: 3971 | P9: 182 | Q9: 7 | R9: 403 | S9: 398 | T9: 56
A10: 45888 | B10: 0.80394125 | C10: 79 | D10: 21 | E10: 0 | F10: 0 | G10: 0 | H10: 2368 | I10: 1784 | J10: 0 | K10: 100 | L10: 176 | M10: 6 | N10: 1 | O10: 3975 | P10: 186 | Q10: 8 | R10: 404 | S10: 398 | T10: 232
A11: 45888 | B11: 0.80395722 | C11: 79 | D11: 26 | E11: 0 | F11: 0 | G11: 0 | H11: 2368 | I11: 1784 | J11: 0 | K11: 100 | L11: 179 | M11: 6 | N11: 0 | O11: 3976 | P11: 190 | Q11: 8 | R11: 404 | S11: 399 | T11: 185
A12: 45888 | B12: 0.80397307 | C12: 79 | D12: 31 | E12: 0 | F12: 0 | G12: 0 | H12: 2368 | I12: 1784 | J12: 0 | K12: 100 | L12: 172 | M12: 7 | N12: 2 | O12: 3979 | P12: 194 | Q12: 8 | R12: 404 | S12: 398 | T12: 33
A13: 45888 | B13: 0.80398889 | C13: 79 | D13: 36 | E13: 0 | F13: 0 | G13: 0 | H13: 2368 | I13: 1784 | J13: 0 | K13: 100 | L13: 179 | M13: 6 | N13: 0 | O13: 3980 | P13: 198 | Q13: 7 | R13: 404 | S13: 397 | T13: 246
... A289: 45888 | B289: 0.80837503 | C289: 79 | D289: 136 | E289: 0 | F289: 0 | G289: 0 | H289: 2368 | I289: 1784 | J289: 0 | K289: 100 | L289: 174 | M289: 6 | N289: 1 | O289: 3987 | P289: 208 | Q289: 8 | R289: 405 | S289: 398 | T289: 178

Sheet Reference_Data
A1: Date | B1: Time | C1: MOD_ID | D1: CMD_CNT | E1: ERROR | F1: MTR_ABS_STEPS | G1: THRM_STATUS | H1: SWIR_OFFSET | I1: MWIR_OFFSET | J1: SCI_ADC_SAMPLES | K1: SCI_ADC_SKIP | L1: SWIR_HIGH | M1: SWIR_MED | N1: SWIR_LOW | O1: MWIR_HIGH | P1: MWIR_MED | Q1: MWIR_LOW | R1: HT_SINK_TEMP | S1: SWIR_TEMP | T1: CRC
A2: 45888 | B2: 0.84766376 | C2: 79 | D2: 4 | E2: 0 | F2: 8 | G2: 0 | H2: 2368 | I2: 1784 | J2: 0 | K2: 100 | L2: 4011 | M2: 348 | N2: 13 | O2: 4011 | P2: 340 | Q2: 12 | R2: 404 | S2: 399 | T2: 150
A3: 45888 | B3: 0.8476795 | C3: 79 | D3: 9 | E3: 0 | F3: 8 | G3: 0 | H3: 2368 | I3: 1784 | J3: 0 | K3: 100 | L3: 4010 | M3: 344 | N3: 12 | O3: 4012 | P3: 345 | Q3: 13 | R3: 404 | S3: 399 | T3: 25
A4: 45888 | B4: 0.84769523 | C4: 79 | D4: 14 | E4: 0 | F4: 8 | G4: 0 | H4: 2368 | I4: 1784 | J4: 0 | K4: 100 | L4: 4010 | M4: 336 | N4: 12 | O4: 4012 | P4: 347 | Q4: 13 | R4: 404 | S4: 398 | T4: 161
A5: 45888 | B5: 0.84771095 | C5: 79 | D5: 19 | E5: 0 | F5: 8 | G5: 0 | H5: 2368 | I5: 1784 | J5: 0 | K5: 100 | L5: 4010 | M5: 334 | N5: 12 | O5: 4012 | P5: 344 | Q5: 13 | R5: 404 | S5: 398 | T5: 173
A6: 45888 | B6: 0.84772677 | C6: 79 | D6: 24 | E6: 0 | F6: 8 | G6: 0 | H6: 2368 | I6: 1784 | J6: 0 | K6: 100 | L6: 4010 | M6: 331 | N6: 12 | O6: 4011 | P6: 341 | Q6: 13 | R6: 404 | S6: 398 | T6: 250
A7: 45888 | B7: 0.84774252 | C7: 79 | D7: 29 | E7: 0 | F7: 8 | G7: 0 | H7: 2368 | I7: 1784 | J7: 0 | K7: 100 | L7: 4011 | M7: 328 | N7: 11 | O7: 4012 | P7: 336 | Q7: 12 | R7: 405 | S7: 398 | T7: 164
A8: 45888 | B8: 0.84775825 | C8: 79 | D8: 34 | E8: 0 | F8: 0 | G8: 0 | H8: 2368 | I8: 1784 | J8: 0 | K8: 100 | L8: 4010 | M8: 326 | N8: 12 | O8: 4012 | P8: 330 | Q8: 11 | R8: 404 | S8: 398 | T8: 5
A9: 45888 | B9: 0.84777397 | C9: 79 | D9: 39 | E9: 0 | F9: 0 | G9: 0 | H9: 2368 | I9: 1784 | J9: 0 | K9: 100 | L9: 4011 | M9: 327 | N9: 11 | O9: 4012 | P9: 328 | Q9: 11 | R9: 404 | S9: 398 | T9: 6
A10: 45888 | B10: 0.84778977 | C10: 79 | D10: 44 | E10: 0 | F10: 0 | G10: 0 | H10: 2368 | I10: 1784 | J10: 0 | K10: 100 | L10: 4010 | M10: 328 | N10: 12 | O10: 4012 | P10: 330 | Q10: 12 | R10: 404 | S10: 398 | T10: 146
A11: 45888 | B11: 0.84780554 | C11: 79 | D11: 49 | E11: 0 | F11: 0 | G11: 0 | H11: 2368 | I11: 1784 | J11: 0 | K11: 100 | L11: 4010 | M11: 331 | N11: 11 | O11: 4012 | P11: 336 | Q11: 12 | R11: 404 | S11: 398 | T11: 44
A12: 45888 | B12: 0.84782128 | C12: 79 | D12: 54 | E12: 0 | F12: 0 | G12: 0 | H12: 2368 | I12: 1784 | J12: 0 | K12: 100 | L12: 4010 | M12: 339 | N12: 12 | O12: 4012 | P12: 344 | Q12: 13 | R12: 405 | S12: 398 | T12: 235
A13: 45888 | B13: 0.84783703 | C13: 79 | D13: 59 | E13: 0 | F13: 0 | G13: 0 | H13: 2368 | I13: 1784 | J13: 0 | K13: 100 | L13: 4010 | M13: 363 | N13: 12 | O13: 4012 | P13: 358 | Q13: 13 | R13: 405 | S13: 398 | T13: 179
... A289: 45888 | B289: 0.8521988 | C289: 79 | D289: 159 | E289: 0 | F289: 0 | G289: 0 | H289: 2368 | I289: 1784 | J289: 0 | K289: 100 | L289: 4009 | M289: 336 | N289: 12 | O289: 4011 | P289: 368 | Q289: 14 | R289: 405 | S289: 398 | T289: 76

Sheet Sample_Data
A1: Date | B1: Time | C1: MOD_ID | D1: CMD_CNT | E1: ERROR | F1: MTR_ABS_STEPS | G1: THRM_STATUS | H1: SWIR_OFFSET | I1: MWIR_OFFSET | J1: SCI_ADC_SAMPLES | K1: SCI_ADC_SKIP | L1: SWIR_HIGH | M1: SWIR_MED | N1: SWIR_LOW | O1: MWIR_HIGH | P1: MWIR_MED | Q1: MWIR_LOW | R1: HT_SINK_TEMP | S1: SWIR_TEMP | T1: CRC
A2: 45888 | B2: 0.83732279 | C2: 79 | D2: 239 | E2: 0 | F2: 8 | G2: 0 | H2: 2368 | I2: 1784 | J2: 0 | K2: 100 | L2: 4010 | M2: 315 | N2: 11 | O2: 4011 | P2: 303 | Q2: 11 | R2: 404 | S2: 399 | T2: 131
A3: 45888 | B3: 0.8373385 | C3: 79 | D3: 244 | E3: 0 | F3: 8 | G3: 0 | H3: 2368 | I3: 1784 | J3: 0 | K3: 100 | L3: 4010 | M3: 310 | N3: 11 | O3: 4011 | P3: 306 | Q3: 11 | R3: 405 | S3: 398 | T3: 86
A4: 45888 | B4: 0.83735429 | C4: 79 | D4: 249 | E4: 0 | F4: 8 | G4: 0 | H4: 2368 | I4: 1784 | J4: 0 | K4: 100 | L4: 4010 | M4: 305 | N4: 11 | O4: 4012 | P4: 308 | Q4: 11 | R4: 404 | S4: 398 | T4: 77
A5: 45888 | B5: 0.83737002 | C5: 79 | D5: 254 | E5: 0 | F5: 8 | G5: 0 | H5: 2368 | I5: 1784 | J5: 0 | K5: 100 | L5: 4010 | M5: 300 | N5: 10 | O5: 4012 | P5: 307 | Q5: 11 | R5: 405 | S5: 398 | T5: 153
A6: 45888 | B6: 0.83738574 | C6: 79 | D6: 3 | E6: 0 | F6: 8 | G6: 0 | H6: 2368 | I6: 1784 | J6: 0 | K6: 100 | L6: 4011 | M6: 298 | N6: 11 | O6: 4012 | P6: 306 | Q6: 11 | R6: 404 | S6: 399 | T6: 12
A7: 45888 | B7: 0.83740148 | C7: 79 | D7: 8 | E7: 0 | F7: 8 | G7: 0 | H7: 2368 | I7: 1784 | J7: 0 | K7: 100 | L7: 4010 | M7: 296 | N7: 11 | O7: 4012 | P7: 304 | Q7: 11 | R7: 405 | S7: 398 | T7: 246
A8: 45888 | B8: 0.83741719 | C8: 79 | D8: 13 | E8: 0 | F8: 0 | G8: 0 | H8: 2368 | I8: 1784 | J8: 0 | K8: 100 | L8: 4011 | M8: 294 | N8: 11 | O8: 4012 | P8: 301 | Q8: 11 | R8: 405 | S8: 398 | T8: 236
A9: 45888 | B9: 0.83743312 | C9: 79 | D9: 18 | E9: 0 | F9: 0 | G9: 0 | H9: 2368 | I9: 1784 | J9: 0 | K9: 100 | L9: 4009 | M9: 294 | N9: 11 | O9: 4012 | P9: 300 | Q9: 11 | R9: 405 | S9: 398 | T9: 250
A10: 45888 | B10: 0.83744882 | C10: 79 | D10: 23 | E10: 0 | F10: 0 | G10: 0 | H10: 2368 | I10: 1784 | J10: 0 | K10: 100 | L10: 4010 | M10: 296 | N10: 9 | O10: 4012 | P10: 303 | Q10: 11 | R10: 405 | S10: 398 | T10: 113
A11: 45888 | B11: 0.83746456 | C11: 79 | D11: 28 | E11: 0 | F11: 0 | G11: 0 | H11: 2368 | I11: 1784 | J11: 0 | K11: 100 | L11: 4010 | M11: 299 | N11: 11 | O11: 4012 | P11: 308 | Q11: 11 | R11: 404 | S11: 398 | T11: 117
A12: 45888 | B12: 0.83748028 | C12: 79 | D12: 33 | E12: 0 | F12: 0 | G12: 0 | H12: 2368 | I12: 1784 | J12: 0 | K12: 100 | L12: 4011 | M12: 306 | N12: 10 | O12: 4012 | P12: 315 | Q12: 11 | R12: 405 | S12: 398 | T12: 23
A13: 45888 | B13: 0.83749601 | C13: 79 | D13: 38 | E13: 0 | F13: 0 | G13: 0 | H13: 2368 | I13: 1784 | J13: 0 | K13: 100 | L13: 4011 | M13: 323 | N13: 12 | O13: 4012 | P13: 326 | Q13: 11 | R13: 404 | S13: 399 | T13: 26
... A289: 45888 | B289: 0.84186337 | C289: 79 | D289: 138 | E289: 0 | F289: 0 | G289: 0 | H289: 2368 | I289: 1784 | J289: 0 | K289: 100 | L289: 4011 | M289: 302 | N289: 11 | O289: 4012 | P289: 336 | Q289: 12 | R289: 404 | S289: 398 | T289: 130

Sheet Analysis
I1: SWIR | U1: MWIR
A2: Offset | I2: 760 | U2: 1350
A3: Grad | C3: Reference | F3: Spectralon MC | I3: 38.6 | J3: Reflectance | R3: Spectralon MC | U3: 71.5 | V3: Reflectance
A5: Abs Steps | C5: SWIR High | D5: SWIR Med | E5: SWIR Low | F5: SWIR High | G5: SWIR Med | H5: SWIR Low | I5: SWIR | J5: SWIR High | K5: SWIR Med | L5: SWIR Low | O5: MWIR High | P5: MWIR Med | Q5: MWIR High | R5: MWIR High | S5: MWIR Med | T5: MWIR High | U5: MWIR | V5: MWIR High | W5: MWIR Med | X5: MWIR High
A6: 100 | C6: =Reference_Data!L2-Dark!L2 -> 3837 | D6: =Reference_Data!M2-Dark!M2 -> 342 | E6: =Reference_Data!N2-Dark!N2 -> 11 | F6: =Sample_Data!L2-Dark!L2 -> 3836 | G6: =Sample_Data!M2-Dark!M2 -> 309 | H6: =Sample_Data!N2-Dark!N2 -> 9 | I6: =$I$3*(A6/320)+$I$2 -> 772.0625 | J6: =F6/C6 -> 0.99973938 | K6: =G6/D6 -> 0.90350877 | L6: =H6/E6 -> 0.81818182 | O6: =Reference_Data!O2-Dark!O2 -> 64 | P6: =Reference_Data!P2-Dark!P2 -> 185 | Q6: =Reference_Data!Q2-Dark!Q2 -> 6 | R6: =Sample_Data!O2-Dark!O2 -> 64 | S6: =Sample_Data!P2-Dark!P2 -> 148 | T6: =Sample_Data!Q2-Dark!Q2 -> 5 | U6: =$U$3*(A6/320)+$U$2 -> 1372.3438 | V6: =R6/O6 -> 1 | W6: =S6/P6 -> 0.8 | X6: =T6/Q6 -> 0.83333333
A7: =A6+30 -> 130 | C7: =Reference_Data!L3-Dark!L3 -> 3844 | D7: =Reference_Data!M3-Dark!M3 -> 338 | E7: =Reference_Data!N3-Dark!N3 -> 12 | F7: =Sample_Data!L3-Dark!L3 -> 3844 | G7: =Sample_Data!M3-Dark!M3 -> 304 | H7: =Sample_Data!N3-Dark!N3 -> 11 | I7: =$I$3*(A7/320)+$I$2 -> 775.68125 | J7: =F7/C7 -> 1 | K7: =G7/D7 -> 0.89940828 | L7: =H7/E7 -> 0.91666667 | O7: =Reference_Data!O3-Dark!O3 -> 62 | P7: =Reference_Data!P3-Dark!P3 -> 187 | Q7: =Reference_Data!Q3-Dark!Q3 -> 7 | R7: =Sample_Data!O3-Dark!O3 -> 61 | S7: =Sample_Data!P3-Dark!P3 -> 148 | T7: =Sample_Data!Q3-Dark!Q3 -> 5 | U7: =$U$3*(A7/320)+$U$2 -> 1379.0469 | V7: =R7/O7 -> 0.98387097 | W7: =S7/P7 -> 0.79144385 | X7: =T7/Q7 -> 0.71428571
A8: =A7+30 -> 160 | C8: =Reference_Data!L4-Dark!L4 -> 3840 | D8: =Reference_Data!M4-Dark!M4 -> 330 | E8: =Reference_Data!N4-Dark!N4 -> 11 | F8: =Sample_Data!L4-Dark!L4 -> 3840 | G8: =Sample_Data!M4-Dark!M4 -> 299 | H8: =Sample_Data!N4-Dark!N4 -> 10 | I8: =$I$3*(A8/320)+$I$2 -> 779.3 | J8: =F8/C8 -> 1 | K8: =G8/D8 -> 0.90606061 | L8: =H8/E8 -> 0.90909091 | O8: =Reference_Data!O4-Dark!O4 -> 58 | P8: =Reference_Data!P4-Dark!P4 -> 186 | Q8: =Reference_Data!Q4-Dark!Q4 -> 7 | R8: =Sample_Data!O4-Dark!O4 -> 58 | S8: =Sample_Data!P4-Dark!P4 -> 147 | T8: =Sample_Data!Q4-Dark!Q4 -> 5 | U8: =$U$3*(A8/320)+$U$2 -> 1385.75 | V8: =R8/O8 -> 1 | W8: =S8/P8 -> 0.79032258 | X8: =T8/Q8 -> 0.71428571
A9: =A8+30 -> 190 | C9: =Reference_Data!L5-Dark!L5 -> 3845 | D9: =Reference_Data!M5-Dark!M5 -> 328 | E9: =Reference_Data!N5-Dark!N5 -> 11 | F9: =Sample_Data!L5-Dark!L5 -> 3845 | G9: =Sample_Data!M5-Dark!M5 -> 294 | H9: =Sample_Data!N5-Dark!N5 -> 9 | I9: =$I$3*(A9/320)+$I$2 -> 782.91875 | J9: =F9/C9 -> 1 | K9: =G9/D9 -> 0.89634146 | L9: =H9/E9 -> 0.81818182 | O9: =Reference_Data!O5-Dark!O5 -> 54 | P9: =Reference_Data!P5-Dark!P5 -> 178 | Q9: =Reference_Data!Q5-Dark!Q5 -> 7 | R9: =Sample_Data!O5-Dark!O5 -> 54 | S9: =Sample_Data!P5-Dark!P5 -> 141 | T9: =Sample_Data!Q5-Dark!Q5 -> 5 | U9: =$U$3*(A9/320)+$U$2 -> 1392.4531 | V9: =R9/O9 -> 1 | W9: =S9/P9 -> 0.79213483 | X9: =T9/Q9 -> 0.71428571
A10: =A9+30 -> 220 | C10: =Reference_Data!L6-Dark!L6 -> 3840 | D10: =Reference_Data!M6-Dark!M6 -> 325 | E10: =Reference_Data!N6-Dark!N6 -> 12 | F10: =Sample_Data!L6-Dark!L6 -> 3841 | G10: =Sample_Data!M6-Dark!M6 -> 292 | H10: =Sample_Data!N6-Dark!N6 -> 11 | I10: =$I$3*(A10/320)+$I$2 -> 786.5375 | J10: =F10/C10 -> 1.0002604 | K10: =G10/D10 -> 0.89846154 | L10: =H10/E10 -> 0.91666667 | O10: =Reference_Data!O6-Dark!O6 -> 50 | P10: =Reference_Data!P6-Dark!P6 -> 173 | Q10: =Reference_Data!Q6-Dark!Q6 -> 7 | R10: =Sample_Data!O6-Dark!O6 -> 51 | S10: =Sample_Data!P6-Dark!P6 -> 138 | T10: =Sample_Data!Q6-Dark!Q6 -> 5 | U10: =$U$3*(A10/320)+$U$2 -> 1399.1562 | V10: =R10/O10 -> 1.02 | W10: =S10/P10 -> 0.79768786 | X10: =T10/Q10 -> 0.71428571
A11: =A10+30 -> 250 | C11: =Reference_Data!L7-Dark!L7 -> 3840 | D11: =Reference_Data!M7-Dark!M7 -> 322 | E11: =Reference_Data!N7-Dark!N7 -> 11 | F11: =Sample_Data!L7-Dark!L7 -> 3839 | G11: =Sample_Data!M7-Dark!M7 -> 290 | H11: =Sample_Data!N7-Dark!N7 -> 11 | I11: =$I$3*(A11/320)+$I$2 -> 790.15625 | J11: =F11/C11 -> 0.99973958 | K11: =G11/D11 -> 0.90062112 | L11: =H11/E11 -> 1 | O11: =Reference_Data!O7-Dark!O7 -> 48 | P11: =Reference_Data!P7-Dark!P7 -> 164 | Q11: =Reference_Data!Q7-Dark!Q7 -> 5 | R11: =Sample_Data!O7-Dark!O7 -> 48 | S11: =Sample_Data!P7-Dark!P7 -> 132 | T11: =Sample_Data!Q7-Dark!Q7 -> 4 | U11: =$U$3*(A11/320)+$U$2 -> 1405.8594 | V11: =R11/O11 -> 1 | W11: =S11/P11 -> 0.80487805 | X11: =T11/Q11 -> 0.8
A12: =A11+30 -> 280 | C12: =Reference_Data!L8-Dark!L8 -> 3830 | D12: =Reference_Data!M8-Dark!M8 -> 320 | E12: =Reference_Data!N8-Dark!N8 -> 11 | F12: =Sample_Data!L8-Dark!L8 -> 3831 | G12: =Sample_Data!M8-Dark!M8 -> 288 | H12: =Sample_Data!N8-Dark!N8 -> 10 | I12: =$I$3*(A12/320)+$I$2 -> 793.775 | J12: =F12/C12 -> 1.0002611 | K12: =G12/D12 -> 0.9 | L12: =H12/E12 -> 0.90909091 | O12: =Reference_Data!O8-Dark!O8 -> 43 | P12: =Reference_Data!P8-Dark!P8 -> 152 | Q12: =Reference_Data!Q8-Dark!Q8 -> 5 | R12: =Sample_Data!O8-Dark!O8 -> 43 | S12: =Sample_Data!P8-Dark!P8 -> 123 | T12: =Sample_Data!Q8-Dark!Q8 -> 5 | U12: =$U$3*(A12/320)+$U$2 -> 1412.5625 | V12: =R12/O12 -> 1 | W12: =S12/P12 -> 0.80921053 | X12: =T12/Q12 -> 1
A13: =A12+30 -> 310 | C13: =Reference_Data!L9-Dark!L9 -> 3833 | D13: =Reference_Data!M9-Dark!M9 -> 321 | E13: =Reference_Data!N9-Dark!N9 -> 9 | F13: =Sample_Data!L9-Dark!L9 -> 3831 | G13: =Sample_Data!M9-Dark!M9 -> 288 | H13: =Sample_Data!N9-Dark!N9 -> 9 | I13: =$I$3*(A13/320)+$I$2 -> 797.39375 | J13: =F13/C13 -> 0.99947822 | K13: =G13/D13 -> 0.89719626 | L13: =H13/E13 -> 1 | O13: =Reference_Data!O9-Dark!O9 -> 41 | P13: =Reference_Data!P9-Dark!P9 -> 146 | Q13: =Reference_Data!Q9-Dark!Q9 -> 4 | R13: =Sample_Data!O9-Dark!O9 -> 41 | S13: =Sample_Data!P9-Dark!P9 -> 118 | T13: =Sample_Data!Q9-Dark!Q9 -> 4 | U13: =$U$3*(A13/320)+$U$2 -> 1419.2656 | V13: =R13/O13 -> 1 | W13: =S13/P13 -> 0.80821918 | X13: =T13/Q13 -> 1
A14: =A13+30 -> 340 | C14: =Reference_Data!L10-Dark!L10 -> 3834 | D14: =Reference_Data!M10-Dark!M10 -> 322 | E14: =Reference_Data!N10-Dark!N10 -> 11 | F14: =Sample_Data!L10-Dark!L10 -> 3834 | G14: =Sample_Data!M10-Dark!M10 -> 290 | H14: =Sample_Data!N10-Dark!N10 -> 8 | I14: =$I$3*(A14/320)+$I$2 -> 801.0125 | J14: =F14/C14 -> 1 | K14: =G14/D14 -> 0.90062112 | L14: =H14/E14 -> 0.72727273 | O14: =Reference_Data!O10-Dark!O10 -> 37 | P14: =Reference_Data!P10-Dark!P10 -> 144 | Q14: =Reference_Data!Q10-Dark!Q10 -> 4 | R14: =Sample_Data!O10-Dark!O10 -> 37 | S14: =Sample_Data!P10-Dark!P10 -> 117 | T14: =Sample_Data!Q10-Dark!Q10 -> 3 | U14: =$U$3*(A14/320)+$U$2 -> 1425.9688 | V14: =R14/O14 -> 1 | W14: =S14/P14 -> 0.8125 | X14: =T14/Q14 -> 0.75
A15: =A14+30 -> 370 | C15: =Reference_Data!L11-Dark!L11 -> 3831 | D15: =Reference_Data!M11-Dark!M11 -> 325 | E15: =Reference_Data!N11-Dark!N11 -> 11 | F15: =Sample_Data!L11-Dark!L11 -> 3831 | G15: =Sample_Data!M11-Dark!M11 -> 293 | H15: =Sample_Data!N11-Dark!N11 -> 11 | I15: =$I$3*(A15/320)+$I$2 -> 804.63125 | J15: =F15/C15 -> 1 | K15: =G15/D15 -> 0.90153846 | L15: =H15/E15 -> 1 | O15: =Reference_Data!O11-Dark!O11 -> 36 | P15: =Reference_Data!P11-Dark!P11 -> 146 | Q15: =Reference_Data!Q11-Dark!Q11 -> 4 | R15: =Sample_Data!O11-Dark!O11 -> 36 | S15: =Sample_Data!P11-Dark!P11 -> 118 | T15: =Sample_Data!Q11-Dark!Q11 -> 3 | U15: =$U$3*(A15/320)+$U$2 -> 1432.6719 | V15: =R15/O15 -> 1 | W15: =S15/P15 -> 0.80821918 | X15: =T15/Q15 -> 0.75
A16: =A15+30 -> 400 | C16: =Reference_Data!L12-Dark!L12 -> 3838 | D16: =Reference_Data!M12-Dark!M12 -> 332 | E16: =Reference_Data!N12-Dark!N12 -> 10 | F16: =Sample_Data!L12-Dark!L12 -> 3839 | G16: =Sample_Data!M12-Dark!M12 -> 299 | H16: =Sample_Data!N12-Dark!N12 -> 8 | I16: =$I$3*(A16/320)+$I$2 -> 808.25 | J16: =F16/C16 -> 1.0002606 | K16: =G16/D16 -> 0.90060241 | L16: =H16/E16 -> 0.8 | O16: =Reference_Data!O12-Dark!O12 -> 33 | P16: =Reference_Data!P12-Dark!P12 -> 150 | Q16: =Reference_Data!Q12-Dark!Q12 -> 5 | R16: =Sample_Data!O12-Dark!O12 -> 33 | S16: =Sample_Data!P12-Dark!P12 -> 121 | T16: =Sample_Data!Q12-Dark!Q12 -> 3 | U16: =$U$3*(A16/320)+$U$2 -> 1439.375 | V16: =R16/O16 -> 1 | W16: =S16/P16 -> 0.80666667 | X16: =T16/Q16 -> 0.6
A17: =A16+30 -> 430 | C17: =Reference_Data!L13-Dark!L13 -> 3831 | D17: =Reference_Data!M13-Dark!M13 -> 357 | E17: =Reference_Data!N13-Dark!N13 -> 12 | F17: =Sample_Data!L13-Dark!L13 -> 3832 | G17: =Sample_Data!M13-Dark!M13 -> 317 | H17: =Sample_Data!N13-Dark!N13 -> 12 | I17: =$I$3*(A17/320)+$I$2 -> 811.86875 | J17: =F17/C17 -> 1.000261 | K17: =G17/D17 -> 0.88795518 | L17: =H17/E17 -> 1 | O17: =Reference_Data!O13-Dark!O13 -> 32 | P17: =Reference_Data!P13-Dark!P13 -> 160 | Q17: =Reference_Data!Q13-Dark!Q13 -> 6 | R17: =Sample_Data!O13-Dark!O13 -> 32 | S17: =Sample_Data!P13-Dark!P13 -> 128 | T17: =Sample_Data!Q13-Dark!Q13 -> 4 | U17: =$U$3*(A17/320)+$U$2 -> 1446.0781 | V17: =R17/O17 -> 1 | W17: =S17/P17 -> 0.8 | X17: =T17/Q17 -> 0.66666667
A18: =A17+30 -> 460 | C18: =Reference_Data!L14-Dark!L14 -> 3834 | D18: =Reference_Data!M14-Dark!M14 -> 382 | E18: =Reference_Data!N14-Dark!N14 -> 12 | F18: =Sample_Data!L14-Dark!L14 -> 3834 | G18: =Sample_Data!M14-Dark!M14 -> 338 | H18: =Sample_Data!N14-Dark!N14 -> 13 | I18: =$I$3*(A18/320)+$I$2 -> 815.4875 | J18: =F18/C18 -> 1 | K18: =G18/D18 -> 0.88481675 | L18: =H18/E18 -> 1.0833333 | O18: =Reference_Data!O14-Dark!O14 -> 28 | P18: =Reference_Data!P14-Dark!P14 -> 169 | Q18: =Reference_Data!Q14-Dark!Q14 -> 5 | R18: =Sample_Data!O14-Dark!O14 -> 29 | S18: =Sample_Data!P14-Dark!P14 -> 134 | T18: =Sample_Data!Q14-Dark!Q14 -> 4 | U18: =$U$3*(A18/320)+$U$2 -> 1452.7812 | V18: =R18/O18 -> 1.0357143 | W18: =S18/P18 -> 0.79289941 | X18: =T18/Q18 -> 0.8
... A318: =A317+30 -> 9460 | C318: =Reference_Data!L314-Dark!L314 -> 0 | D318: =Reference_Data!M314-Dark!M314 -> 0 | E318: =Reference_Data!N314-Dark!N314 -> 0 | F318: =Sample_Data!L314-Dark!L314 -> 0 | G318: =Sample_Data!M314-Dark!M314 -> 0 | H318: =Sample_Data!N314-Dark!N314 -> 0 | I318: =$I$3*(A318/320)+$I$2 -> 1901.1125 | J318: =F318/C318 -> #DIV/0! | K318: =G318/D318 -> #DIV/0! | L318: =H318/E318 -> #DIV/0! | O318: =Reference_Data!O314-Dark!O314 -> 0 | P318: =Reference_Data!P314-Dark!P314 -> 0 | Q318: =Reference_Data!Q314-Dark!Q314 -> 0 | R318: =Sample_Data!O314-Dark!O314 -> 0 | S318: =Sample_Data!P314-Dark!P314 -> 0 | T318: =Sample_Data!Q314-Dark!Q314 -> 0 | U318: =$U$3*(A318/320)+$U$2 -> 3463.7188 | V318: =R318/O318 -> #DIV/0! | W318: =S318/P318 -> #DIV/0! | X318: =T318/Q318 -> #DIV/0!

Sheet Kaolinite
A1: PDS_VERSION_ID = PDS3
A3: /* FILE CHARACTERISTICS */
A5: RECORD_TYPE = STREAM
A6: FILE_RECORDS = 2420
A7: LABEL_RECORDS = 137
A8: ^TABLE = 138
A10: /* IDENTIFICATION KEYWORDS */
A13: DATA_SET_ID = "MRO-M-CRISM-4-SPECLIB-V1.0"
A14: PRODUCT_ID = "LAKA04"
A15: PRODUCT_NAME = "KA-EAC-004"
A16: PRODUCT_TYPE = "VNIR-MIR"
A17: PRODUCT_CREATION_TIME = 2005-11-11T12:45:51
... A26: MRO:SPECIMEN_DESC = "POORLY ORDERED KAOLINITE."
A27: MRO:SPECIMEN_CLASS_NAME = "NATURAL | B27: SOLID | C27: EARTH | D27: MINERAL | E27: UNCLASSIFIED
A28: PHYLLOSILICATE | B28: UNCLASSIFIED | C28: KAOLINITE"
A30: MRO:SPECIMEN_MIN_PARTICLE_SIZE = 0.000 <MM>
A31: MRO:SPECIMEN_MAX_PARTICLE_SIZE = 0.004 <MM>
A32: MRO:SPECIMEN_COLLECT_LOCATION_DESC= "UNK"
A33: MRO:SPECIMEN_CURRENT_LOCATION_NAME = "UNIVERSITY OF WINNIPEG"
A34: MRO:SPECIMEN_LAST_OWNER_NAME = "EDWARD A. CLOUTIS"
A37: GROUP = SEGMENT_1_PARAMETERS
A38: INSTRUMENT_ID = "BDVNIR_RELAB"
A39: INSTRUMENT_NAME = "RELAB BIDIRECTIONAL REFLECTANCE SPECTROMETER"
A41: INSTRUMENT_HOST_NAME = "RELAB"
A42: EARTH_BASE_INSTITUTION_NAME = "BROWN UNIVERSITY"
A43: SAMPLING_PARAMETER_NAME = "WAVELENGTH"
A44: MINIMUM_SAMPLING_PARAMETER = 0.30000 <MICROMETERS>
... A78: SAMPLING_DESC = "THE EXACT WAVELENGTHS CONTAINED WITHIN THE ORIGINAL
A79: INDIVIDUAL SPECTRAL SEGMENTS | B79: AND THE RELATIVE SCALING FACTORS OF EACH
A80: SEGMENT | B80: USED TO CREATE THE COMBINED SPECTRUM MAY OR MAY NOT BE DOCUMENTED IN
A81: THE REFERENCES PROVIDED. IN SOME CASES THE INDIVIDUAL SPECTRA USED TO CREATE
A82: THE COMBINED SPECTRUM ARE AVAILABLE TO THE USER."
A83: MRO:MEASUREMENT_MIN_RESOLUTION = 4 <CM**-1>
A84: MRO:MEASUREMENT_MAX_RESOLUTION = 4 <CM**-1>
A85: MRO:MEASUREMENT_GEOMETRY_TYPE = "BICONICAL"
A86: INCIDENCE_ANGLE = 'N/A'
A87: EMISSION_ANGLE = 'N/A'
A88: PHASE_ANGLE = 'N/A'
A89: AZIMUTH = 'N/A'
A90: MRO:MEASUREMENT_GEOMETRY_DESC = "N/A"
...
